Workbook

Sheet How to Use
A1: HelpDesk — API Test Cases
A3: What this workbook is
A4: The API test cases for the HelpDesk app, ready to run manually (Postman / Swagger) and then automate with Rest Assured + TestNG.
A6: Sheets
A7: API Test Cases — every test case. Fill in the yellow-header columns as you execute.
A8: Business Rules — the app's rules (your requirements). Each test case links to one in the "Rule Ref" column.
A9: Permission Matrix — who can do what. Every ✅ is a positive test, every ❌ a negative test.
A10: Defects Found — bugs found while designing these tests, in bug-report format. Add your own bugs here.
A11: Summary — counts that update automatically as you fill in the Status column.
A13: Environment
A14: Base URL: http://localhost:8080/api Swagger UI: http://localhost:8080/swagger-ui.html
A15: Database: localhost:5433 · database / user / password = helpdesk
... A24: Example of a filled-in execution (format only)
A25: TC ID | B25: Status | C25: Actual Result | D25: Executed By | E25: Date | F25: Remarks
A26: AUTH-001 | B26: Pass | C26: 200 OK, token returned, role CUSTOMER, expiresAt +8h | D26: Your name | E26: 2026-10-01 | F26: —

Sheet Summary
A1: Test Execution Summary
A3: Total test cases | B3: =COUNTA('API Test Cases'!$A$2:$A$172)
A4: Executed (Pass + Fail) | B4: =B8+B9
A5: Pass rate (of executed) | B5: =IFERROR(B8/B4,0)
A6: By Status | B6: Count
A7: Not Run | B7: =COUNTIF('API Test Cases'!$O$2:$O$172,A7)
A8: Pass | B8: =COUNTIF('API Test Cases'!$O$2:$O$172,A8)
A9: Fail | B9: =COUNTIF('API Test Cases'!$O$2:$O$172,A9)
A10: Blocked | B10: =COUNTIF('API Test Cases'!$O$2:$O$172,A10)
A11: Skipped | B11: =COUNTIF('API Test Cases'!$O$2:$O$172,A11)
A13: By Module | B13: Count
A14: Authentication | B14: =COUNTIF('API Test Cases'!$B$2:$B$172,A14)
A15: Tickets - Create | B15: =COUNTIF('API Test Cases'!$B$2:$B$172,A15)
A16: Tickets - View & Search | B16: =COUNTIF('API Test Cases'!$B$2:$B$172,A16)
A17: Tickets - Update | B17: =COUNTIF('API Test Cases'!$B$2:$B$172,A17)
A18: Ticket Lifecycle | B18: =COUNTIF('API Test Cases'!$B$2:$B$172,A18)
A19: Comments | B19: =COUNTIF('API Test Cases'!$B$2:$B$172,A19)
A20: Tickets - Delete | B20: =COUNTIF('API Test Cases'!$B$2:$B$172,A20)
A21: Dashboard Stats | B21: =COUNTIF('API Test Cases'!$B$2:$B$172,A21)
A22: SLA | B22: =COUNTIF('API Test Cases'!$B$2:$B$172,A22)
A23: User Management | B23: =COUNTIF('API Test Cases'!$B$2:$B$172,A23)
A24: Errors & General | B24: =COUNTIF('API Test Cases'!$B$2:$B$172,A24)
A26: By Test Type | B26: Count
A27: Positive | B27: =COUNTIF('API Test Cases'!$F$2:$F$172,A27)
A28: Negative | B28: =COUNTIF('API Test Cases'!$F$2:$F$172,A28)
A29: Boundary | B29: =COUNTIF('API Test Cases'!$F$2:$F$172,A29)
A30: Security | B30: =COUNTIF('API Test Cases'!$F$2:$F$172,A30)
A31: Integration | B31: =COUNTIF('API Test Cases'!$F$2:$F$172,A31)
A33: By Priority | B33: Count
A34: P1 | B34: =COUNTIF('API Test Cases'!$M$2:$M$172,A34)
A35: P2 | B35: =COUNTIF('API Test Cases'!$M$2:$M$172,A35)
A36: P3 | B36: =COUNTIF('API Test Cases'!$M$2:$M$172,A36)
A38: Known defects (expected to fail) | B38: =COUNTIF('API Test Cases'!$S$2:$S$172,"KNOWN DEFECT*")
A40: Priority: P1 = must pass before release (core flows & security) · P2 = important · P3 = edge cases

Sheet API Test Cases
A1: TC ID | B1: Module | C1: Method | D1: Endpoint | E1: Test Scenario | F1: Test Type | G1: Role | H1: Preconditions | I1: Request / Test Data | J1: Expected Status | K1: Expected Result | L1: Rule Ref | M1: Priority | N1: Automate? | O1: Status | P1: Actual Result | Q1: Executed By | R1: Date | S1: Remarks
A2: AUTH-001 | B2: Authentication | C2: POST | D2: /auth/login | E2: Login with valid customer credentials | F2: Positive | G2: No token | H2: Demo customer exists | I2: {"email":"customer@helpdesk.local","password":"Customer@123"} | J2: 200 | K2: Body has token, tokenType = "Bearer", expiresAt ≈ now + 8h, user.role = CUSTOMER, user.email correct | L2: BR-03 | M2: P1 | N2: Yes | O2: Not Run
A3: AUTH-002 | B3: Authentication | C3: POST | D3: /auth/login | E3: Login with valid agent credentials | F3: Positive | G3: No token | H3: Demo agent exists | I3: {"email":"agent1@helpdesk.local","password":"Agent@123"} | J3: 200 | K3: user.role = AGENT | L3: BR-03 | M3: P1 | N3: Yes | O3: Not Run
A4: AUTH-003 | B4: Authentication | C4: POST | D4: /auth/login | E4: Login with valid admin credentials | F4: Positive | G4: No token | H4: Demo admin exists | I4: {"email":"admin@helpdesk.local","password":"Admin@123"} | J4: 200 | K4: user.role = ADMIN | L4: BR-03 | M4: P1 | N4: Yes | O4: Not Run
A5: AUTH-004 | B5: Authentication | C5: POST | D5: /auth/login | E5: Login email is case-insensitive | F5: Positive | G5: No token | H5: Demo customer exists | I5: {"email":"CUSTOMER@HELPDESK.LOCAL","password":"Customer@123"} | J5: 200 | K5: Login succeeds, user.email = customer@helpdesk.local | L5: BR-03 | M5: P3 | N5: Yes | O5: Not Run
A6: AUTH-005 | B6: Authentication | C6: POST | D6: /auth/login | E6: Login with wrong password | F6: Negative | G6: No token | H6: Demo customer exists | I6: {"email":"customer@helpdesk.local","password":"wrong"} | J6: 401 | K6: message = "Invalid email or password"; no token in response | L6: BR-03 | M6: P1 | N6: Yes | O6: Not Run
A7: AUTH-006 | B7: Authentication | C7: POST | D7: /auth/login | E7: Login with unregistered email gives the same message as wrong password | F7: Security | G7: No token | H7: — | I7: {"email":"nobody@x.com","password":"any"} | J7: 401 | K7: message = "Invalid email or password" (identical to wrong password, so attackers can't find valid emails) | L7: BR-03 | M7: P2 | N7: Yes | O7: Not Run
A8: AUTH-007 | B8: Authentication | C8: POST | D8: /auth/login | E8: Login without email | F8: Negative | G8: No token | H8: — | I8: {"password":"Customer@123"} | J8: 400 | K8: message = "Validation failed"; fieldErrors has "email" | L8: BR-18 | M8: P2 | N8: Yes | O8: Not Run
A9: AUTH-008 | B9: Authentication | C9: POST | D9: /auth/login | E9: Login without password | F9: Negative | G9: No token | H9: — | I9: {"email":"customer@helpdesk.local"} | J9: 400 | K9: fieldErrors has "password" | L9: BR-18 | M9: P2 | N9: Yes | O9: Not Run
A10: AUTH-009 | B10: Authentication | C10: POST | D10: /auth/login | E10: Login with malformed JSON | F10: Negative | G10: No token | H10: — | I10: { not json | J10: 400 | K10: message = "Malformed request" | L10: BR-18 | M10: P3 | N10: Yes | O10: Not Run
A11: AUTH-010 | B11: Authentication | C11: POST | D11: /auth/login | E11: Deactivated user cannot log in | F11: Negative | G11: No token | H11: Admin has deactivated agent2 | I11: {"email":"agent2@helpdesk.local","password":"Agent@123"} | J11: 401 | K11: message = "Account is deactivated" | L11: BR-03 | M11: P1 | N11: Yes | O11: Not Run | S11: Re-activate agent2 afterwards
A12: AUTH-011 | B12: Authentication | C12: POST | D12: /auth/login | E12: Login response never exposes the password | F12: Security | G12: No token | H12: — | I12: Valid customer login | J12: 200 | K12: Response (including user object) has no password / passwordHash field | L12: BR-03 | M12: P1 | N12: Yes | O12: Not Run
A13: AUTH-012 | B13: Authentication | C13: POST | D13: /auth/register | E13: Register a new customer | F13: Positive | G13: No token | H13: Email not yet registered | I13: {"email":"new.user1@test.com","password":"Password1","fullName":"New User"} | J13: 201 | K13: Body has token + user; user.role = CUSTOMER; user.active = true | L13: BR-02 | M13: P1 | N13: Yes | O13: Not Run | S13: Use a unique email every run (e.g. add a timestamp)
A14: AUTH-013 | B14: Authentication | C14: POST | D14: /auth/register | E14: Registered email is stored in lower case | F14: Positive | G14: No token | H14: — | I14: {"email":"Mixed.Case@Test.com", ...} | J14: 201 | K14: user.email = "mixed.case@test.com" | L14: BR-02 | M14: P3 | N14: Yes | O14: Not Run
A15: AUTH-014 | B15: Authentication | C15: POST | D15: /auth/register | E15: Register with an email that already exists (different case) | F15: Negative | G15: No token | H15: customer@helpdesk.local exists | I15: {"email":"Customer@Helpdesk.local","password":"Password1","fullName":"Dup"} | J15: 409 | K15: message contains "already exists" | L15: BR-02 | M15: P1 | N15: Yes | O15: Not Run
A16: AUTH-015 | B16: Authentication | C16: POST | D16: /auth/register | E16: Register with invalid email format | F16: Negative | G16: No token | H16: — | I16: email = "not-an-email" | J16: 400 | K16: fieldErrors has "email" | L16: BR-02 | M16: P2 | N16: Yes | O16: Not Run
A17: AUTH-016 | B17: Authentication | C17: POST | D17: /auth/register | E17: Password with 7 characters is rejected | F17: Boundary | G17: No token | H17: — | I17: password = "Pass123" (7) | J17: 400 | K17: fieldErrors.password = "size must be between 8 and 72" | L17: BR-02 | M17: P2 | N17: Yes | O17: Not Run
A18: AUTH-017 | B18: Authentication | C18: POST | D18: /auth/register | E18: Password with exactly 8 characters is accepted | F18: Boundary | G18: No token | H18: — | I18: password = "Pass1234" (8) | J18: 201 | K18: User created | L18: BR-02 | M18: P2 | N18: Yes | O18: Not Run
A19: AUTH-018 | B19: Authentication | C19: POST | D19: /auth/register | E19: Password with 72 characters accepted, 73 rejected | F19: Boundary | G19: No token | H19: — | I19: password length 72, then 73 | J19: 201 / 400 | K19: 72 → created; 73 → fieldErrors has "password" | L19: BR-02 | M19: P3 | N19: Yes | O19: Not Run
A20: AUTH-019 | B20: Authentication | C20: POST | D20: /auth/register | E20: Full name blank or only spaces | F20: Negative | G20: No token | H20: — | I20: fullName = " " | J20: 400 | K20: fieldErrors.fullName = "must not be blank" | L20: BR-02 | M20: P2 | N20: Yes | O20: Not Run
A21: AUTH-020 | B21: Authentication | C21: POST | D21: /auth/register | E21: Full name 120 characters accepted, 121 rejected | F21: Boundary | G21: No token | H21: — | I21: fullName length 120, then 121 | J21: 201 / 400 | K21: 120 → created; 121 → fieldErrors has "fullName" | L21: BR-02 | M21: P3 | N21: Yes | O21: Not Run
A22: AUTH-021 | B22: Authentication | C22: POST | D22: /auth/register | E22: Cannot register as ADMIN by adding a role field | F22: Security | G22: No token | H22: — | I22: {"email":"hacker@test.com","password":"Password1","fullName":"H","role":"ADMIN"} | J22: 201 | K22: user.role = CUSTOMER (role field is ignored) | L22: BR-02 | M22: P1 | N22: Yes | O22: Not Run | S22: Privilege-escalation check
A23: AUTH-022 | B23: Authentication | C23: POST | D23: /auth/register | E23: Newly registered user can log in | F23: Integration | G23: No token | H23: User registered in previous step | I23: Same email + password on /auth/login | J23: 200 | K23: Login succeeds with role CUSTOMER | L23: BR-02 | M23: P2 | N23: Yes | O23: Not Run
A24: AUTH-023 | B24: Authentication | C24: GET | D24: /auth/me | E24: Get current user with a valid token | F24: Positive | G24: Customer | H24: Logged in as customer | I24: — | J24: 200 | K24: Returns the logged-in user's id, email, fullName, role | L24: BR-01 | M24: P1 | N24: Yes | O24: Not Run
A25: AUTH-024 | B25: Authentication | C25: GET | D25: /auth/me | E25: Call without a token | F25: Negative | G25: No token | H25: — | I25: No Authorization header | J25: 401 | K25: message = "Missing or invalid token" | L25: BR-01 | M25: P1 | N25: Yes | O25: Not Run
A26: AUTH-025 | B26: Authentication | C26: GET | D26: /auth/me | E26: Call with a tampered token | F26: Security | G26: No token | H26: — | I26: Valid token with one character changed | J26: 401 | K26: message = "Missing or invalid token" | L26: BR-01 | M26: P1 | N26: Yes | O26: Not Run
A27: AUTH-026 | B27: Authentication | C27: GET | D27: /auth/me | E27: Call with token but without the "Bearer " prefix | F27: Negative | G27: No token | H27: — | I27: Authorization: <token> | J27: 401 | K27: Rejected | L27: BR-01 | M27: P3 | N27: Yes | O27: Not Run
A28: AUTH-027 | B28: Authentication | C28: GET | D28: /auth/me | E28: Expired token is rejected | F28: Security | G28: Customer | H28: Start app with JWT_TTL=PT1M; log in; wait > 1 minute | I28: Old token | J28: 401 | K28: message = "Missing or invalid token" | L28: BR-01 | M28: P2 | N28: Yes | O28: Not Run | S28: Needs app restarted with a short token lifetime
A29: AUTH-028 | B29: Authentication | C29: GET | D29: /auth/me | E29: Deactivated user's existing token stops working | F29: Security | G29: Agent | H29: Log in as agent2 and keep the token; admin then deactivates agent2 | I29: agent2's old token | J29: 401 | K29: Access denied once the account is deactivated | L29: BR-03 | M29: P1 | N29: Yes | O29: Not Run | S29: KNOWN DEFECT BUG-001: currently returns 200 — old token keeps working for up to 8h
A30: TKC-001 | B30: Tickets - Create | C30: POST | D30: /tickets | E30: Customer raises a valid ticket | F30: Positive | G30: Customer | H30: Logged in as customer | I30: {"subject":"Payment failed","description":"Card charged but order not placed"} | J30: 201 | K30: Location header = /api/tickets/{id}; status OPEN; priority MEDIUM; assignee null; sla.breached false; customerEmail = customer's own email | L30: BR-07 | M30: P1 | N30: Yes | O30: Not Run
A31: TKC-002 | B31: Tickets - Create | C31: POST | D31: /tickets | E31: Raise ticket with a category | F31: Positive | G31: Customer | H31: Logged in as customer | I31: ... "category":"BILLING" | J31: 201 | K31: category = BILLING | L31: BR-06 | M31: P2 | N31: Yes | O31: Not Run
A32: TKC-003 | B32: Tickets - Create | C32: POST | D32: /tickets | E32: Raise ticket without a category | F32: Positive | G32: Customer | H32: Logged in as customer | I32: No category field | J32: 201 | K32: category = null | L32: BR-06 | M32: P2 | N32: Yes | O32: Not Run
A33: TKC-004 | B33: Tickets - Create | C33: POST | D33: /tickets | E33: SLA due time of a new ticket is 24h after creation | F33: Positive | G33: Customer | H33: Logged in as customer | I33: Valid ticket | J33: 201 | K33: sla.dueAt − createdAt = exactly 24 hours | L33: BR-07 | M33: P1 | N33: Yes | O33: Not Run
A34: TKC-005 | B34: Tickets - Create | C34: POST | D34: /tickets | E34: Customer cannot raise a ticket on someone else's behalf | F34: Security | G34: Customer | H34: Logged in as customer | I34: ... "customerEmail":"other@x.com" | J34: 201 | K34: customerEmail = customer's OWN email (sent value ignored) | L34: BR-05 | M34: P1 | N34: Yes | O34: Not Run
A35: TKC-006 | B35: Tickets - Create | C35: POST | D35: /tickets | E35: Agent raises a ticket for a customer | F35: Positive | G35: Agent | H35: Logged in as agent | I35: {"subject":"s","description":"d","customerEmail":"Phone.Caller@Test.com"} | J35: 201 | K35: customerEmail = "phone.caller@test.com" | L35: BR-05 | M35: P2 | N35: Yes | O35: Not Run
A36: TKC-007 | B36: Tickets - Create | C36: POST | D36: /tickets | E36: Agent raises a ticket without customerEmail | F36: Negative | G36: Agent | H36: Logged in as agent | I36: {"subject":"s","description":"d"} | J36: 400 | K36: message = "customerEmail is required when staff create a ticket" | L36: BR-05 | M36: P2 | N36: Yes | O36: Not Run
A37: TKC-008 | B37: Tickets - Create | C37: POST | D37: /tickets | E37: Agent sends invalid customerEmail | F37: Negative | G37: Agent | H37: Logged in as agent | I37: customerEmail = "abc" | J37: 400 | K37: fieldErrors has "customerEmail" | L37: BR-05 | M37: P3 | N37: Yes | O37: Not Run
A38: TKC-009 | B38: Tickets - Create | C38: POST | D38: /tickets | E38: Subject missing | F38: Negative | G38: Customer | H38: Logged in as customer | I38: No subject | J38: 400 | K38: fieldErrors has "subject" | L38: BR-06 | M38: P1 | N38: Yes | O38: Not Run
A39: TKC-010 | B39: Tickets - Create | C39: POST | D39: /tickets | E39: Subject only spaces | F39: Negative | G39: Customer | H39: Logged in as customer | I39: subject = " " | J39: 400 | K39: fieldErrors.subject = "must not be blank" | L39: BR-06 | M39: P2 | N39: Yes | O39: Not Run
A40: TKC-011 | B40: Tickets - Create | C40: POST | D40: /tickets | E40: Subject 200 characters accepted, 201 rejected | F40: Boundary | G40: Customer | H40: Logged in as customer | I40: subject length 200, then 201 | J40: 201 / 400 | K40: 200 → created; 201 → fieldErrors has "subject" | L40: BR-06 | M40: P2 | N40: Yes | O40: Not Run
...

Sheet Business Rules
A1: Rule ID | B1: Area | C1: Rule (what the app must do) | D1: Test Cases
A2: BR-01 | B2: Access | C2: Every API needs a valid login token (Authorization: Bearer <token>), except /api/auth/login and /api/auth/register. Missing, invalid or expired token → 401. | D2: =COUNTIF('API Test Cases'!$L$2:$L$172,"*"&A2&"*")
A3: BR-02 | B3: Registration | C3: Self-registration always creates a CUSTOMER. Email must be valid and unique (case-insensitive) and is stored in lower case. Password 8–72 characters. Full name required, max 120. | D3: =COUNTIF('API Test Cases'!$L$2:$L$172,"*"&A3&"*")
A4: BR-03 | B4: Login | C4: Correct email + password → token valid for 8 hours. Wrong email OR wrong password → 401 with the same message (does not reveal which one was wrong). Deactivated accounts cannot log in. | D4: =COUNTIF('API Test Cases'!$L$2:$L$172,"*"&A4&"*")
A5: BR-04 | B5: Ticket visibility | C5: Customers can only see their own tickets. Asking for someone else's ticket returns 404 (as if it does not exist). Agents and admins see all tickets. | D5: =COUNTIF('API Test Cases'!$L$2:$L$172,"*"&A5&"*")
A6: BR-05 | B6: Ticket owner | C6: A customer's ticket is always linked to their own email, even if they send a different customerEmail. Agents/admins creating a ticket must send customerEmail. | D6: =COUNTIF('API Test Cases'!$L$2:$L$172,"*"&A6&"*")
A7: BR-06 | B7: Ticket validation | C7: Subject required, max 200 chars. Description required, max 5000 chars. Category optional: BILLING, BUG, FEATURE_REQUEST, ACCOUNT, OTHER. Leading/trailing spaces are trimmed. | D7: =COUNTIF('API Test Cases'!$L$2:$L$172,"*"&A7&"*")
A8: BR-07 | B8: New ticket defaults | C8: A new ticket is OPEN, priority MEDIUM, unassigned, not breached, SLA due = created time + 24 hours. | D8: =COUNTIF('API Test Cases'!$L$2:$L$172,"*"&A8&"*")
A9: BR-08 | B9: Lifecycle | C9: Allowed moves: OPEN→IN_PROGRESS/CLOSED; IN_PROGRESS→WAITING_ON_CUSTOMER/RESOLVED; WAITING_ON_CUSTOMER→IN_PROGRESS/RESOLVED; RESOLVED→IN_PROGRESS/CLOSED. CLOSED is final. Any other move → 409. | D9: =COUNTIF('API Test Cases'!$L$2:$L$172,"*"&A9&"*")
A10: BR-09 | B10: Auto-assign | C10: Moving an unassigned ticket to IN_PROGRESS assigns it to the person who moved it. An already-assigned ticket keeps its assignee. | D10: =COUNTIF('API Test Cases'!$L$2:$L$172,"*"&A10&"*")
A11: BR-10 | B11: Timestamps | C11: resolvedAt is set when a ticket becomes RESOLVED and cleared when it is reopened. closedAt is set when it becomes CLOSED. | D11: =COUNTIF('API Test Cases'!$L$2:$L$172,"*"&A11&"*")
A12: BR-11 | B12: Ticket updates | C12: Only agents/admins can update tickets (status, priority, category, assignee). Assignee must be an active agent or admin. Sending assigneeId and unassign together → 400. | D12: =COUNTIF('API Test Cases'!$L$2:$L$172,"*"&A12&"*")
A13: BR-12 | B13: SLA deadline | C13: SLA due = created time + allowed time for the priority: URGENT 4h, HIGH 8h, MEDIUM 24h, LOW 72h. Changing priority recalculates it from the created time. | D13: =COUNTIF('API Test Cases'!$L$2:$L$172,"*"&A13&"*")
... A21: BR-20 | B21: Dashboard stats | C21: Agents/admins only. Counts per status, plus slaBreached and unassigned — both counted only for tickets not yet RESOLVED/CLOSED. | D21: =COUNTIF('API Test Cases'!$L$2:$L$172,"*"&A21&"*")

Sheet Permission Matrix
A1: Action | B1: Endpoint | C1: Customer | D1: Agent | E1: Admin | F1: No token
A2: Register themselves | B2: POST /auth/register | C2: ✅ | D2: — | E2: — | F2: ✅
A3: Log in | B3: POST /auth/login | C3: ✅ | D3: ✅ | E3: ✅ | F3: ✅
A4: See own profile | B4: GET /auth/me | C4: ✅ | D4: ✅ | E4: ✅ | F4: ❌ 401
A5: Raise a ticket for themselves | B5: POST /tickets | C5: ✅ | D5: — | E5: — | F5: ❌ 401
A6: Raise a ticket for a customer | B6: POST /tickets + customerEmail | C6: ❌ (email ignored) | D6: ✅ | E6: ✅ | F6: ❌ 401
A7: See own tickets | B7: GET /tickets, /tickets/{id} | C7: ✅ | D7: ✅ | E7: ✅ | F7: ❌ 401
A8: See other customers' tickets | B8: GET /tickets/{id} | C8: ❌ 404 | D8: ✅ | E8: ✅ | F8: ❌ 401
A9: Dashboard stats | B9: GET /tickets/stats | C9: ❌ 403 | D9: ✅ | E9: ✅ | F9: ❌ 401
A10: Change status / priority / category / assignee | B10: PATCH /tickets/{id} | C10: ❌ 403 | D10: ✅ | E10: ✅ | F10: ❌ 401
A11: Delete a ticket | B11: DELETE /tickets/{id} | C11: ❌ 403 | D11: ❌ 403 | E11: ✅ | F11: ❌ 401
A12: Reply on a ticket | B12: POST /tickets/{id}/comments | C12: ✅ own only | D12: ✅ | E12: ✅ | F12: ❌ 401
... A17: Update / deactivate a user | B17: PATCH /users/{id} | C17: ❌ 403 | D17: ❌ 403 | E17: ✅ (not self) | F17: ❌ 401
A19: ✅ = allowed → positive test. ❌ = blocked → negative test (the code shows the expected status). — = not applicable.

Sheet Defects Found
A1: Bug ID | B1: Title | C1: Severity | D1: Type | E1: Steps to Reproduce | F1: Expected Result | G1: Actual Result | H1: Found By Test | I1: Status | J1: Jira Link
A2: BUG-001 | B2: Deactivated user's existing token keeps working | C2: High | D2: Security | E2: 1. Log in as agent2@helpdesk.local and copy the token 2. Log in as admin and PATCH /api/users/3 {"active":false} 3. Call GET /api/auth/me with agent2's old token | F2: 401 Unauthorized — a deactivated account should lose access immediately | G2: 200 OK — the old token works until it expires (up to 8 hours) | H2: AUTH (last case) | I2: Open
A3: BUG-002 | B3: A CLOSED ticket can still be edited | C3: Medium | D3: Functional | E3: 1. Create a ticket and PATCH it to {"status":"CLOSED"} 2. PATCH it again with {"priority":"URGENT","assigneeId":3} | F3: 409 Conflict — CLOSED is final, no changes allowed | G3: 200 OK — priority, SLA due time and assignee are changed on a closed ticket | H3: TKU (last case) | I3: Open
A4: BUG-003 | B4: Admin can set a user's name to only spaces (saved as empty) | C4: Low | D4: Validation | E4: 1. Log in as admin 2. PATCH /api/users/{id} with {"fullName":" "} | F4: 400 Bad Request with fieldErrors.fullName (same rule as registration) | G4: 200 OK — fullName is saved as an empty string | H4: USR (last case) | I4: Open
A5: BUG-004 | B5: Some errors don't use the standard error format | C5: Low | D5: API contract | E5: 1. POST /api/tickets with Content-Type: text/plain (415) 2. PUT /api/tickets/1 (405) 3. GET /api/nope (404) | F5: Body has timestamp, status, error, message, path, fieldErrors like all other errors | G5: Body has only timestamp, status, error, path — "message" and "fieldErrors" are missing | H5: ERR cases 2–4 | I5: Open
